[2023-06-14T04:04:58.132+0000] {taskinstance.py:1103} INFO - Dependencies all met for dep_context=non-requeueable deps ti=<TaskInstance: dag_with_python_dependencies.get_sklearn scheduled__2023-06-13T00:00:00+00:00 [queued]>
[2023-06-14T04:04:58.165+0000] {taskinstance.py:1103} INFO - Dependencies all met for dep_context=requeueable deps ti=<TaskInstance: dag_with_python_dependencies.get_sklearn scheduled__2023-06-13T00:00:00+00:00 [queued]>
[2023-06-14T04:04:58.165+0000] {taskinstance.py:1308} INFO - Starting attempt 1 of 1
[2023-06-14T04:04:58.195+0000] {taskinstance.py:1327} INFO - Executing <Task(PythonOperator): get_sklearn> on 2023-06-13 00:00:00+00:00
[2023-06-14T04:04:58.204+0000] {standard_task_runner.py:57} INFO - Started process 2705 to run task
[2023-06-14T04:04:58.209+0000] {standard_task_runner.py:84} INFO - Running: ['***', 'tasks', 'run', 'dag_with_python_dependencies', 'get_sklearn', 'scheduled__2023-06-13T00:00:00+00:00', '--job-id', '1937', '--raw', '--subdir', 'DAGS_FOLDER/dag_avec_extending.py', '--cfg-path', '/tmp/tmp7zvrpjm0']
[2023-06-14T04:04:58.212+0000] {standard_task_runner.py:85} INFO - Job 1937: Subtask get_sklearn
[2023-06-14T04:04:58.336+0000] {task_command.py:410} INFO - Running <TaskInstance: dag_with_python_dependencies.get_sklearn scheduled__2023-06-13T00:00:00+00:00 [running]> on host 4a7ff00e5bd0
[2023-06-14T04:04:58.584+0000] {taskinstance.py:1547} INFO - Exporting env vars: AIRFLOW_CTX_DAG_OWNER='coder2j' AIRFLOW_CTX_DAG_ID='dag_with_python_dependencies' AIRFLOW_CTX_TASK_ID='get_sklearn' AIRFLOW_CTX_EXECUTION_DATE='2023-06-13T00:00:00+00:00' AIRFLOW_CTX_TRY_NUMBER='1' AIRFLOW_CTX_DAG_RUN_ID='scheduled__2023-06-13T00:00:00+00:00'
[2023-06-14T04:04:58.590+0000] {taskinstance.py:1824} ERROR - Task failed with exception
Traceback (most recent call last):
  File "/home/airflow/.local/lib/python3.7/site-packages/airflow/operators/python.py", line 181, in execute
    return_value = self.execute_callable()
  File "/home/airflow/.local/lib/python3.7/site-packages/airflow/operators/python.py", line 198, in execute_callable
    return self.python_callable(*self.op_args, **self.op_kwargs)
  File "/opt/airflow/dags/dag_avec_extending.py", line 14, in get_sklearn
    import sklearn
ModuleNotFoundError: No module named 'sklearn'
[2023-06-14T04:04:58.624+0000] {taskinstance.py:1350} INFO - Marking task as FAILED. dag_id=dag_with_python_dependencies, task_id=get_sklearn, execution_date=20230613T000000, start_date=20230614T040458, end_date=20230614T040458
[2023-06-14T04:04:58.690+0000] {standard_task_runner.py:109} ERROR - Failed to execute job 1937 for task get_sklearn (No module named 'sklearn'; 2705)
[2023-06-14T04:04:58.764+0000] {local_task_job_runner.py:225} INFO - Task exited with return code 1
[2023-06-14T04:04:58.883+0000] {taskinstance.py:2651} INFO - 0 downstream tasks scheduled from follow-on schedule check
