[2023-06-14T03:21:22.978+0000] {taskinstance.py:1103} INFO - Dependencies all met for dep_context=non-requeueable deps ti=<TaskInstance: dag_avec_postgres.create_postgres_table manual__2023-06-14T03:12:57.048807+00:00 [queued]>
[2023-06-14T03:21:22.997+0000] {taskinstance.py:1103} INFO - Dependencies all met for dep_context=requeueable deps ti=<TaskInstance: dag_avec_postgres.create_postgres_table manual__2023-06-14T03:12:57.048807+00:00 [queued]>
[2023-06-14T03:21:22.997+0000] {taskinstance.py:1308} INFO - Starting attempt 5 of 6
[2023-06-14T03:21:23.023+0000] {taskinstance.py:1327} INFO - Executing <Task(PostgresOperator): create_postgres_table> on 2023-06-14 03:12:57.048807+00:00
[2023-06-14T03:21:23.032+0000] {standard_task_runner.py:57} INFO - Started process 1412 to run task
[2023-06-14T03:21:23.035+0000] {standard_task_runner.py:84} INFO - Running: ['***', 'tasks', 'run', 'dag_avec_postgres', 'create_postgres_table', 'manual__2023-06-14T03:12:57.048807+00:00', '--job-id', '1899', '--raw', '--subdir', 'DAGS_FOLDER/dag_avec_postgres.py', '--cfg-path', '/tmp/tmp3m3c9za2']
[2023-06-14T03:21:23.041+0000] {standard_task_runner.py:85} INFO - Job 1899: Subtask create_postgres_table
[2023-06-14T03:21:23.154+0000] {task_command.py:410} INFO - Running <TaskInstance: dag_avec_postgres.create_postgres_table manual__2023-06-14T03:12:57.048807+00:00 [running]> on host 89e558dce6d9
[2023-06-14T03:21:23.321+0000] {taskinstance.py:1547} INFO - Exporting env vars: AIRFLOW_CTX_DAG_OWNER='ismail' AIRFLOW_CTX_DAG_ID='dag_avec_postgres' AIRFLOW_CTX_TASK_ID='create_postgres_table' AIRFLOW_CTX_EXECUTION_DATE='2023-06-14T03:12:57.048807+00:00' AIRFLOW_CTX_TRY_NUMBER='5' AIRFLOW_CTX_DAG_RUN_ID='manual__2023-06-14T03:12:57.048807+00:00'
[2023-06-14T03:21:23.322+0000] {sql.py:262} INFO - Executing: 
            create table if not exist dag_runs (
                dt date,
                dag_id character varying,
                primary key (dt, dag_id)
            )
        
[2023-06-14T03:21:23.342+0000] {base.py:73} INFO - Using connection ID 'postgres_localhost' for task execution.
[2023-06-14T03:21:23.446+0000] {base.py:73} INFO - Using connection ID 'postgres_localhost' for task execution.
[2023-06-14T03:21:23.448+0000] {taskinstance.py:1824} ERROR - Task failed with exception
Traceback (most recent call last):
  File "/home/airflow/.local/lib/python3.7/site-packages/airflow/providers/common/sql/operators/sql.py", line 274, in execute
    **extra_kwargs,
  File "/home/airflow/.local/lib/python3.7/site-packages/airflow/providers/common/sql/hooks/sql.py", line 342, in run
    with closing(self.get_conn()) as conn:
  File "/home/airflow/.local/lib/python3.7/site-packages/airflow/providers/postgres/hooks/postgres.py", line 144, in get_conn
    self.conn = psycopg2.connect(**conn_args)
  File "/home/airflow/.local/lib/python3.7/site-packages/psycopg2/__init__.py", line 122, in connect
    conn = _connect(dsn, connection_factory=connection_factory, **kwasync)
psycopg2.OperationalError: connection to server at "localhost" (127.0.0.1), port 5432 failed: Connection refused
	Is the server running on that host and accepting TCP/IP connections?
connection to server at "localhost" (::1), port 5432 failed: Cannot assign requested address
	Is the server running on that host and accepting TCP/IP connections?

[2023-06-14T03:21:23.469+0000] {taskinstance.py:1350} INFO - Marking task as UP_FOR_RETRY. dag_id=dag_avec_postgres, task_id=create_postgres_table, execution_date=20230614T031257, start_date=20230614T032122, end_date=20230614T032123
[2023-06-14T03:21:23.497+0000] {standard_task_runner.py:109} ERROR - Failed to execute job 1899 for task create_postgres_table (connection to server at "localhost" (127.0.0.1), port 5432 failed: Connection refused
	Is the server running on that host and accepting TCP/IP connections?
connection to server at "localhost" (::1), port 5432 failed: Cannot assign requested address
	Is the server running on that host and accepting TCP/IP connections?
; 1412)
[2023-06-14T03:21:23.542+0000] {local_task_job_runner.py:225} INFO - Task exited with return code 1
[2023-06-14T03:21:23.600+0000] {taskinstance.py:2660} INFO - Skipping mini scheduling run due to exception: SELECT dag_run.state AS dag_run_state, dag_run.id AS dag_run_id, dag_run.dag_id AS dag_run_dag_id, dag_run.queued_at AS dag_run_queued_at, dag_run.execution_date AS dag_run_execution_date, dag_run.start_date AS dag_run_start_date, dag_run.end_date AS dag_run_end_date, dag_run.run_id AS dag_run_run_id, dag_run.creating_job_id AS dag_run_creating_job_id, dag_run.external_trigger AS dag_run_external_trigger, dag_run.run_type AS dag_run_run_type, dag_run.conf AS dag_run_conf, dag_run.data_interval_start AS dag_run_data_interval_start, dag_run.data_interval_end AS dag_run_data_interval_end, dag_run.last_scheduling_decision AS dag_run_last_scheduling_decision, dag_run.dag_hash AS dag_run_dag_hash, dag_run.log_template_id AS dag_run_log_template_id, dag_run.updated_at AS dag_run_updated_at 
FROM dag_run 
WHERE dag_run.dag_id = %(dag_id_1)s AND dag_run.run_id = %(run_id_1)s FOR UPDATE
Traceback (most recent call last):
  File "/home/airflow/.local/lib/python3.7/site-packages/sqlalchemy/engine/base.py", line 1906, in _execute_context
    cursor, statement, parameters, context
  File "/home/airflow/.local/lib/python3.7/site-packages/sqlalchemy/engine/default.py", line 736, in do_execute
    cursor.execute(statement, parameters)
psycopg2.OperationalError: server closed the connection unexpectedly
	This probably means the server terminated abnormally
	before or while processing the request.


The above exception was the direct cause of the following exception:

Traceback (most recent call last):
  File "/home/airflow/.local/lib/python3.7/site-packages/airflow/models/taskinstance.py", line 2611, in schedule_downstream_tasks
    session=session,
  File "/home/airflow/.local/lib/python3.7/site-packages/sqlalchemy/orm/query.py", line 2870, in one
    return self._iter().one()
  File "/home/airflow/.local/lib/python3.7/site-packages/sqlalchemy/orm/query.py", line 2919, in _iter
    execution_options={"_sa_orm_load_options": self.load_options},
  File "/home/airflow/.local/lib/python3.7/site-packages/sqlalchemy/orm/session.py", line 1717, in execute
    result = conn._execute_20(statement, params or {}, execution_options)
  File "/home/airflow/.local/lib/python3.7/site-packages/sqlalchemy/engine/base.py", line 1710, in _execute_20
    return meth(self, args_10style, kwargs_10style, execution_options)
  File "/home/airflow/.local/lib/python3.7/site-packages/sqlalchemy/sql/elements.py", line 335, in _execute_on_connection
    self, multiparams, params, execution_options
  File "/home/airflow/.local/lib/python3.7/site-packages/sqlalchemy/engine/base.py", line 1587, in _execute_clauseelement
    cache_hit=cache_hit,
  File "/home/airflow/.local/lib/python3.7/site-packages/sqlalchemy/engine/base.py", line 1949, in _execute_context
    e, statement, parameters, cursor, context
  File "/home/airflow/.local/lib/python3.7/site-packages/sqlalchemy/engine/base.py", line 2130, in _handle_dbapi_exception
    sqlalchemy_exception, with_traceback=exc_info[2], from_=e
  File "/home/airflow/.local/lib/python3.7/site-packages/sqlalchemy/util/compat.py", line 211, in raise_
    raise exception
  File "/home/airflow/.local/lib/python3.7/site-packages/sqlalchemy/engine/base.py", line 1906, in _execute_context
    cursor, statement, parameters, context
  File "/home/airflow/.local/lib/python3.7/site-packages/sqlalchemy/engine/default.py", line 736, in do_execute
    cursor.execute(statement, parameters)
sqlalchemy.exc.OperationalError: (psycopg2.OperationalError) server closed the connection unexpectedly
	This probably means the server terminated abnormally
	before or while processing the request.

[SQL: SELECT dag_run.state AS dag_run_state, dag_run.id AS dag_run_id, dag_run.dag_id AS dag_run_dag_id, dag_run.queued_at AS dag_run_queued_at, dag_run.execution_date AS dag_run_execution_date, dag_run.start_date AS dag_run_start_date, dag_run.end_date AS dag_run_end_date, dag_run.run_id AS dag_run_run_id, dag_run.creating_job_id AS dag_run_creating_job_id, dag_run.external_trigger AS dag_run_external_trigger, dag_run.run_type AS dag_run_run_type, dag_run.conf AS dag_run_conf, dag_run.data_interval_start AS dag_run_data_interval_start, dag_run.data_interval_end AS dag_run_data_interval_end, dag_run.last_scheduling_decision AS dag_run_last_scheduling_decision, dag_run.dag_hash AS dag_run_dag_hash, dag_run.log_template_id AS dag_run_log_template_id, dag_run.updated_at AS dag_run_updated_at 
FROM dag_run 
WHERE dag_run.dag_id = %(dag_id_1)s AND dag_run.run_id = %(run_id_1)s FOR UPDATE]
[parameters: {'dag_id_1': 'dag_avec_postgres', 'run_id_1': 'manual__2023-06-14T03:12:57.048807+00:00'}]
(Background on this error at: https://sqlalche.me/e/14/e3q8)
