[2023-06-14T00:28:10.827+0000] {taskinstance.py:1103} INFO - Dependencies all met for dep_context=non-requeueable deps ti=<TaskInstance: dag_avec_PythonOperator.bonjour scheduled__2023-06-13T00:00:00+00:00 [queued]>
[2023-06-14T00:28:10.846+0000] {taskinstance.py:1103} INFO - Dependencies all met for dep_context=requeueable deps ti=<TaskInstance: dag_avec_PythonOperator.bonjour scheduled__2023-06-13T00:00:00+00:00 [queued]>
[2023-06-14T00:28:10.846+0000] {taskinstance.py:1308} INFO - Starting attempt 3 of 8
[2023-06-14T00:28:10.878+0000] {taskinstance.py:1327} INFO - Executing <Task(PythonOperator): bonjour> on 2023-06-13 00:00:00+00:00
[2023-06-14T00:28:10.886+0000] {standard_task_runner.py:57} INFO - Started process 6448 to run task
[2023-06-14T00:28:10.891+0000] {standard_task_runner.py:84} INFO - Running: ['***', 'tasks', 'run', 'dag_avec_PythonOperator', 'bonjour', 'scheduled__2023-06-13T00:00:00+00:00', '--job-id', '1647', '--raw', '--subdir', 'DAGS_FOLDER/dag_avec_pythonoperator.py', '--cfg-path', '/tmp/tmpdobxghge']
[2023-06-14T00:28:10.894+0000] {standard_task_runner.py:85} INFO - Job 1647: Subtask bonjour
[2023-06-14T00:28:11.026+0000] {task_command.py:410} INFO - Running <TaskInstance: dag_avec_PythonOperator.bonjour scheduled__2023-06-13T00:00:00+00:00 [running]> on host 857e1d87a73f
[2023-06-14T00:28:11.239+0000] {taskinstance.py:1547} INFO - Exporting env vars: AIRFLOW_CTX_DAG_OWNER='ismail' AIRFLOW_CTX_DAG_ID='dag_avec_PythonOperator' AIRFLOW_CTX_TASK_ID='bonjour' AIRFLOW_CTX_EXECUTION_DATE='2023-06-13T00:00:00+00:00' AIRFLOW_CTX_TRY_NUMBER='3' AIRFLOW_CTX_DAG_RUN_ID='scheduled__2023-06-13T00:00:00+00:00'
[2023-06-14T00:28:11.240+0000] {taskinstance.py:1824} ERROR - Task failed with exception
Traceback (most recent call last):
  File "/home/airflow/.local/lib/python3.7/site-packages/airflow/operators/python.py", line 181, in execute
    return_value = self.execute_callable()
  File "/home/airflow/.local/lib/python3.7/site-packages/airflow/operators/python.py", line 198, in execute_callable
    return self.python_callable(*self.op_args, **self.op_kwargs)
TypeError: bonjour() missing 1 required positional argument: 'nom'
[2023-06-14T00:28:11.270+0000] {taskinstance.py:1350} INFO - Marking task as UP_FOR_RETRY. dag_id=dag_avec_PythonOperator, task_id=bonjour, execution_date=20230613T000000, start_date=20230614T002810, end_date=20230614T002811
[2023-06-14T00:28:11.310+0000] {standard_task_runner.py:109} ERROR - Failed to execute job 1647 for task bonjour (bonjour() missing 1 required positional argument: 'nom'; 6448)
[2023-06-14T00:28:11.357+0000] {local_task_job_runner.py:225} INFO - Task exited with return code 1
[2023-06-14T00:28:11.398+0000] {taskinstance.py:2651} INFO - 0 downstream tasks scheduled from follow-on schedule check
